<?xml version="1.0" encoding="UTF-8"?>
<testsuite name="t2"
           tests="5"
           failures="3"
           errors="0"
           skipped="0"
           time="0.029">
  <properties />
            <testcase name="test2" time="0.003" classname="com.webtest.demo.demo">
                <failure type="java.lang.AssertionError"
                  message="expected [2] but found [1]"
              >
<![CDATA[java.lang.AssertionError: expected [2] but found [1]
  org.testng.Assert.fail(Assert.java:99)
  org.testng.Assert.failNotEquals(Assert.java:1037)
  org.testng.Assert.assertEqualsImpl(Assert.java:140)
  org.testng.Assert.assertEquals(Assert.java:122)
  org.testng.Assert.assertEquals(Assert.java:907)
  org.testng.Assert.assertEquals(Assert.java:917)
  com.webtest.demo.demo.test2(demo.java:19)
  sun.reflect.NativeMethodAccessorImpl.invoke0(Native Method)
  sun.reflect.NativeMethodAccessorImpl.invoke(Unknown Source)
  sun.reflect.DelegatingMethodAccessorImpl.invoke(Unknown Source)
  java.lang.reflect.Method.invoke(Unknown Source)
  org.testng.internal.MethodInvocationHelper.invokeMethod(MethodInvocationHelper.java:132)
  org.testng.internal.TestInvoker.invokeMethod(TestInvoker.java:599)
  org.testng.internal.TestInvoker.invokeTestMethod(TestInvoker.java:174)
  org.testng.internal.MethodRunner.runInSequence(MethodRunner.java:46)
  org.testng.internal.TestInvoker$MethodInvocationAgent.invoke(TestInvoker.java:822)
  org.testng.internal.TestInvoker.invokeTestMethods(TestInvoker.java:147)
  org.testng.internal.TestMethodWorker.invokeTestMethods(TestMethodWorker.java:146)
  org.testng.internal.TestMethodWorker.run(TestMethodWorker.java:128)
  java.util.ArrayList.forEach(Unknown Source)
  org.testng.TestRunner.privateRun(TestRunner.java:764)
  org.testng.TestRunner.run(TestRunner.java:585)
  org.testng.SuiteRunner.runTest(SuiteRunner.java:384)
  org.testng.SuiteRunner.runSequentially(SuiteRunner.java:378)
  org.testng.SuiteRunner.privateRun(SuiteRunner.java:337)
  org.testng.SuiteRunner.run(SuiteRunner.java:286)
  org.testng.SuiteRunnerWorker.runSuite(SuiteRunnerWorker.java:53)
  org.testng.SuiteRunnerWorker.run(SuiteRunnerWorker.java:96)
  org.testng.TestNG.runSuitesSequentially(TestNG.java:1218)
  org.testng.TestNG.runSuitesLocally(TestNG.java:1140)
  org.testng.TestNG.runSuites(TestNG.java:1069)
  org.testng.TestNG.run(TestNG.java:1037)
  org.testng.remote.AbstractRemoteTestNG.run(AbstractRemoteTestNG.java:115)
  org.testng.remote.RemoteTestNG.initAndRun(RemoteTestNG.java:251)
  org.testng.remote.RemoteTestNG.main(RemoteTestNG.java:77)
]]>
      </failure>

          </testcase>
            <testcase name="test5" time="0.002" classname="com.webtest.demo.demo">
                <failure type="java.lang.AssertionError"
                  message="expected [1] but found [3]"
              >
<![CDATA[java.lang.AssertionError: expected [1] but found [3]
  org.testng.Assert.fail(Assert.java:99)
  org.testng.Assert.failNotEquals(Assert.java:1037)
  org.testng.Assert.assertEqualsImpl(Assert.java:140)
  org.testng.Assert.assertEquals(Assert.java:122)
  org.testng.Assert.assertEquals(Assert.java:907)
  org.testng.Assert.assertEquals(Assert.java:917)
  com.webtest.demo.demo.test5(demo.java:34)
  sun.reflect.NativeMethodAccessorImpl.invoke0(Native Method)
  sun.reflect.NativeMethodAccessorImpl.invoke(Unknown Source)
  sun.reflect.DelegatingMethodAccessorImpl.invoke(Unknown Source)
  java.lang.reflect.Method.invoke(Unknown Source)
  org.testng.internal.MethodInvocationHelper.invokeMethod(MethodInvocationHelper.java:132)
  org.testng.internal.TestInvoker.invokeMethod(TestInvoker.java:599)
  org.testng.internal.TestInvoker.invokeTestMethod(TestInvoker.java:174)
  org.testng.internal.MethodRunner.runInSequence(MethodRunner.java:46)
  org.testng.internal.TestInvoker$MethodInvocationAgent.invoke(TestInvoker.java:822)
  org.testng.internal.TestInvoker.invokeTestMethods(TestInvoker.java:147)
  org.testng.internal.TestMethodWorker.invokeTestMethods(TestMethodWorker.java:146)
  org.testng.internal.TestMethodWorker.run(TestMethodWorker.java:128)
  java.util.ArrayList.forEach(Unknown Source)
  org.testng.TestRunner.privateRun(TestRunner.java:764)
  org.testng.TestRunner.run(TestRunner.java:585)
  org.testng.SuiteRunner.runTest(SuiteRunner.java:384)
  org.testng.SuiteRunner.runSequentially(SuiteRunner.java:378)
  org.testng.SuiteRunner.privateRun(SuiteRunner.java:337)
  org.testng.SuiteRunner.run(SuiteRunner.java:286)
  org.testng.SuiteRunnerWorker.runSuite(SuiteRunnerWorker.java:53)
  org.testng.SuiteRunnerWorker.run(SuiteRunnerWorker.java:96)
  org.testng.TestNG.runSuitesSequentially(TestNG.java:1218)
  org.testng.TestNG.runSuitesLocally(TestNG.java:1140)
  org.testng.TestNG.runSuites(TestNG.java:1069)
  org.testng.TestNG.run(TestNG.java:1037)
  org.testng.remote.AbstractRemoteTestNG.run(AbstractRemoteTestNG.java:115)
  org.testng.remote.RemoteTestNG.initAndRun(RemoteTestNG.java:251)
  org.testng.remote.RemoteTestNG.main(RemoteTestNG.java:77)
]]>
      </failure>

          </testcase>
            <testcase name="test4" time="0.002" classname="com.webtest.demo.demo">
                <failure type="java.lang.AssertionError"
                  message="expected [1] but found [2]"
              >
<![CDATA[java.lang.AssertionError: expected [1] but found [2]
  org.testng.Assert.fail(Assert.java:99)
  org.testng.Assert.failNotEquals(Assert.java:1037)
  org.testng.Assert.assertEqualsImpl(Assert.java:140)
  org.testng.Assert.assertEquals(Assert.java:122)
  org.testng.Assert.assertEquals(Assert.java:907)
  org.testng.Assert.assertEquals(Assert.java:917)
  com.webtest.demo.demo.test4(demo.java:29)
  sun.reflect.NativeMethodAccessorImpl.invoke0(Native Method)
  sun.reflect.NativeMethodAccessorImpl.invoke(Unknown Source)
  sun.reflect.DelegatingMethodAccessorImpl.invoke(Unknown Source)
  java.lang.reflect.Method.invoke(Unknown Source)
  org.testng.internal.MethodInvocationHelper.invokeMethod(MethodInvocationHelper.java:132)
  org.testng.internal.TestInvoker.invokeMethod(TestInvoker.java:599)
  org.testng.internal.TestInvoker.invokeTestMethod(TestInvoker.java:174)
  org.testng.internal.MethodRunner.runInSequence(MethodRunner.java:46)
  org.testng.internal.TestInvoker$MethodInvocationAgent.invoke(TestInvoker.java:822)
  org.testng.internal.TestInvoker.invokeTestMethods(TestInvoker.java:147)
  org.testng.internal.TestMethodWorker.invokeTestMethods(TestMethodWorker.java:146)
  org.testng.internal.TestMethodWorker.run(TestMethodWorker.java:128)
  java.util.ArrayList.forEach(Unknown Source)
  org.testng.TestRunner.privateRun(TestRunner.java:764)
  org.testng.TestRunner.run(TestRunner.java:585)
  org.testng.SuiteRunner.runTest(SuiteRunner.java:384)
  org.testng.SuiteRunner.runSequentially(SuiteRunner.java:378)
  org.testng.SuiteRunner.privateRun(SuiteRunner.java:337)
  org.testng.SuiteRunner.run(SuiteRunner.java:286)
  org.testng.SuiteRunnerWorker.runSuite(SuiteRunnerWorker.java:53)
  org.testng.SuiteRunnerWorker.run(SuiteRunnerWorker.java:96)
  org.testng.TestNG.runSuitesSequentially(TestNG.java:1218)
  org.testng.TestNG.runSuitesLocally(TestNG.java:1140)
  org.testng.TestNG.runSuites(TestNG.java:1069)
  org.testng.TestNG.run(TestNG.java:1037)
  org.testng.remote.AbstractRemoteTestNG.run(AbstractRemoteTestNG.java:115)
  org.testng.remote.RemoteTestNG.initAndRun(RemoteTestNG.java:251)
  org.testng.remote.RemoteTestNG.main(RemoteTestNG.java:77)
]]>
      </failure>

          </testcase>
  
  
            <testcase name="test3" time="0.003" classname="com.webtest.demo.demo" />
                <testcase name="test1" time="0.019" classname="com.webtest.demo.demo" />
      
</testsuite>
